[2025-04-14 16:53:25 +0000] [6666] [ERROR] Exception in worker process
Traceback (most recent call last):
  File "/home/runner/workspace/.pythonlibs/lib/python3.11/site-packages/gunicorn/arbiter.py", line 580, in spawn_worker
    worker.init_process()
  File "/home/runner/workspace/.pythonlibs/lib/python3.11/site-packages/gunicorn/workers/base.py", line 136, in init_process
    self.load_wsgi()
  File "/home/runner/workspace/.pythonlibs/lib/python3.11/site-packages/gunicorn/workers/base.py", line 148, in load_wsgi
    self.wsgi = self.app.wsgi()
                ^^^^^^^^^^^^^^^
  File "/home/runner/workspace/.pythonlibs/lib/python3.11/site-packages/gunicorn/app/base.py", line 64, in wsgi
    self.callable = self.load()
                    ^^^^^^^^^^^
  File "/home/runner/workspace/.pythonlibs/lib/python3.11/site-packages/gunicorn/app/wsgiapp.py", line 55, in load
    return self.load_wsgiapp()
           ^^^^^^^^^^^^^^^^^^^
  File "/home/runner/workspace/.pythonlibs/lib/python3.11/site-packages/gunicorn/app/wsgiapp.py", line 45, in load_wsgiapp
    return util.import_app(self.app_uri)
           ^^^^^^^^^^^^^^^^^^^^^^^^^^^^^
  File "/home/runner/workspace/.pythonlibs/lib/python3.11/site-packages/gunicorn/util.py", line 326, in import_app
    mod = importlib.import_module(module)
          ^^^^^^^^^^^^^^^^^^^^^^^^^^^^^^^
  File "/nix/store/clx0mcir7qw8zk36zbr4jra789g3knf6-python3-3.11.10/lib/python3.11/importlib/__init__.py", line 126, in import_module
    return _bootstrap._gcd_import(name[level:], package, level)
           ^^^^^^^^^^^^^^^^^^^^^^^^^^^^^^^^^^^^^^^^^^^^^^^^^^^^
  File "<frozen importlib._bootstrap>", line 1204, in _gcd_import
  File "<frozen importlib._bootstrap>", line 1176, in _find_and_load
  File "<frozen importlib._bootstrap>", line 1147, in _find_and_load_unlocked
  File "<frozen importlib._bootstrap>", line 690, in _load_unlocked
  File "<frozen importlib._bootstrap_external>", line 940, in exec_module
  File "<frozen importlib._bootstrap>", line 241, in _call_with_frames_removed
  File "/home/runner/workspace/main.py", line 1, in <module>
    from app import app # noqa: F401
    ^^^^^^^^^^^^^^^^^^^
  File "/home/runner/workspace/app.py", line 7, in <module>
    from logic.b_jobs.jobHeading import job_heading_bp
  File "/home/runner/workspace/logic/b_jobs/jobHeading.py", line 8, in <module>
    from logic.b_jobs.jobSync import save_index
  File "/home/runner/workspace/logic/b_jobs/jobSync.py", line 8, in <module>
    from logic.b_jobs.jobLayout import get_recent_jobs
  File "/home/runner/workspace/logic/b_jobs/jobLayout.py", line 11, in <module>
    from logic.b_jobs.jobSync import save_index
ImportError: cannot import name 'save_index' from partially initialized module 'logic.b_jobs.jobSync' (most likely due to a circular import) (/home/runner/workspace/logic/b_jobs/jobSync.py)
[2025-04-14 16:53:25 +0000] [6655] [ERROR] Worker (pid:6666) exited with code 3
[2025-04-14 16:53:25 +0000] [6655] [ERROR] Shutting down: Master
[2025-04-14 16:53:25 +0000] [6655] [ERROR] Reason: Worker failed to boot.